No error handlers are registered, logging exception.
Traceback (most recent call last):
  File "/Users/mariakondakova/Recipe-bot/venv/lib/python3.11/site-packages/telegram/ext/_updater.py", line 743, in _network_loop_retry
    if not await do_action():
           ^^^^^^^^^^^^^^^^^
  File "/Users/mariakondakova/Recipe-bot/venv/lib/python3.11/site-packages/telegram/ext/_updater.py", line 737, in do_action
    return action_cb_task.result()
           ^^^^^^^^^^^^^^^^^^^^^^^
  File "/Users/mariakondakova/Recipe-bot/venv/lib/python3.11/site-packages/telegram/ext/_updater.py", line 367, in polling_action_cb
    updates = await self.bot.get_updates(
              ^^^^^^^^^^^^^^^^^^^^^^^^^^^
  File "/Users/mariakondakova/Recipe-bot/venv/lib/python3.11/site-packages/telegram/ext/_extbot.py", line 647, in get_updates
    updates = await super().get_updates(
              ^^^^^^^^^^^^^^^^^^^^^^^^^^
  File "/Users/mariakondakova/Recipe-bot/venv/lib/python3.11/site-packages/telegram/_bot.py", line 4421, in get_updates
    await self._post(
  File "/Users/mariakondakova/Recipe-bot/venv/lib/python3.11/site-packages/telegram/_bot.py", line 617, in _post
    return await self._do_post(
           ^^^^^^^^^^^^^^^^^^^^
  File "/Users/mariakondakova/Recipe-bot/venv/lib/python3.11/site-packages/telegram/ext/_extbot.py", line 351, in _do_post
    return await super()._do_post(
           ^^^^^^^^^^^^^^^^^^^^^^^
  File "/Users/mariakondakova/Recipe-bot/venv/lib/python3.11/site-packages/telegram/_bot.py", line 646, in _do_post
    result = await request.post(
             ^^^^^^^^^^^^^^^^^^^
  File "/Users/mariakondakova/Recipe-bot/venv/lib/python3.11/site-packages/telegram/request/_baserequest.py", line 202, in post
    result = await self._request_wrapper(
             ^^^^^^^^^^^^^^^^^^^^^^^^^^^^
  File "/Users/mariakondakova/Recipe-bot/venv/lib/python3.11/site-packages/telegram/request/_baserequest.py", line 385, in _request_wrapper
    raise Conflict(message)
telegram.error.Conflict: Conflict: terminated by other getUpdates request; make sure that only one bot instance is running
No error handlers are registered, logging exception.
Traceback (most recent call last):
  File "/Users/mariakondakova/Recipe-bot/venv/lib/python3.11/site-packages/telegram/ext/_updater.py", line 743, in _network_loop_retry
    if not await do_action():
           ^^^^^^^^^^^^^^^^^
  File "/Users/mariakondakova/Recipe-bot/venv/lib/python3.11/site-packages/telegram/ext/_updater.py", line 737, in do_action
    return action_cb_task.result()
           ^^^^^^^^^^^^^^^^^^^^^^^
  File "/Users/mariakondakova/Recipe-bot/venv/lib/python3.11/site-packages/telegram/ext/_updater.py", line 367, in polling_action_cb
    updates = await self.bot.get_updates(
              ^^^^^^^^^^^^^^^^^^^^^^^^^^^
  File "/Users/mariakondakova/Recipe-bot/venv/lib/python3.11/site-packages/telegram/ext/_extbot.py", line 647, in get_updates
    updates = await super().get_updates(
              ^^^^^^^^^^^^^^^^^^^^^^^^^^
  File "/Users/mariakondakova/Recipe-bot/venv/lib/python3.11/site-packages/telegram/_bot.py", line 4421, in get_updates
    await self._post(
  File "/Users/mariakondakova/Recipe-bot/venv/lib/python3.11/site-packages/telegram/_bot.py", line 617, in _post
    return await self._do_post(
           ^^^^^^^^^^^^^^^^^^^^
  File "/Users/mariakondakova/Recipe-bot/venv/lib/python3.11/site-packages/telegram/ext/_extbot.py", line 351, in _do_post
    return await super()._do_post(
           ^^^^^^^^^^^^^^^^^^^^^^^
  File "/Users/mariakondakova/Recipe-bot/venv/lib/python3.11/site-packages/telegram/_bot.py", line 646, in _do_post
    result = await request.post(
             ^^^^^^^^^^^^^^^^^^^
  File "/Users/mariakondakova/Recipe-bot/venv/lib/python3.11/site-packages/telegram/request/_baserequest.py", line 202, in post
    result = await self._request_wrapper(
             ^^^^^^^^^^^^^^^^^^^^^^^^^^^^
  File "/Users/mariakondakova/Recipe-bot/venv/lib/python3.11/site-packages/telegram/request/_baserequest.py", line 385, in _request_wrapper
    raise Conflict(message)
telegram.error.Conflict: Conflict: terminated by other getUpdates request; make sure that only one bot instance is running
No error handlers are registered, logging exception.
Traceback (most recent call last):
  File "/Users/mariakondakova/Recipe-bot/venv/lib/python3.11/site-packages/telegram/ext/_updater.py", line 743, in _network_loop_retry
    if not await do_action():
           ^^^^^^^^^^^^^^^^^
  File "/Users/mariakondakova/Recipe-bot/venv/lib/python3.11/site-packages/telegram/ext/_updater.py", line 737, in do_action
    return action_cb_task.result()
           ^^^^^^^^^^^^^^^^^^^^^^^
  File "/Users/mariakondakova/Recipe-bot/venv/lib/python3.11/site-packages/telegram/ext/_updater.py", line 367, in polling_action_cb
    updates = await self.bot.get_updates(
              ^^^^^^^^^^^^^^^^^^^^^^^^^^^
  File "/Users/mariakondakova/Recipe-bot/venv/lib/python3.11/site-packages/telegram/ext/_extbot.py", line 647, in get_updates
    updates = await super().get_updates(
              ^^^^^^^^^^^^^^^^^^^^^^^^^^
  File "/Users/mariakondakova/Recipe-bot/venv/lib/python3.11/site-packages/telegram/_bot.py", line 4421, in get_updates
    await self._post(
  File "/Users/mariakondakova/Recipe-bot/venv/lib/python3.11/site-packages/telegram/_bot.py", line 617, in _post
    return await self._do_post(
           ^^^^^^^^^^^^^^^^^^^^
  File "/Users/mariakondakova/Recipe-bot/venv/lib/python3.11/site-packages/telegram/ext/_extbot.py", line 351, in _do_post
    return await super()._do_post(
           ^^^^^^^^^^^^^^^^^^^^^^^
  File "/Users/mariakondakova/Recipe-bot/venv/lib/python3.11/site-packages/telegram/_bot.py", line 646, in _do_post
    result = await request.post(
             ^^^^^^^^^^^^^^^^^^^
  File "/Users/mariakondakova/Recipe-bot/venv/lib/python3.11/site-packages/telegram/request/_baserequest.py", line 202, in post
    result = await self._request_wrapper(
             ^^^^^^^^^^^^^^^^^^^^^^^^^^^^
  File "/Users/mariakondakova/Recipe-bot/venv/lib/python3.11/site-packages/telegram/request/_baserequest.py", line 385, in _request_wrapper
    raise Conflict(message)
telegram.error.Conflict: Conflict: terminated by other getUpdates request; make sure that only one bot instance is running
No error handlers are registered, logging exception.
Traceback (most recent call last):
  File "/Users/mariakondakova/Recipe-bot/venv/lib/python3.11/site-packages/telegram/ext/_updater.py", line 743, in _network_loop_retry
    if not await do_action():
           ^^^^^^^^^^^^^^^^^
  File "/Users/mariakondakova/Recipe-bot/venv/lib/python3.11/site-packages/telegram/ext/_updater.py", line 737, in do_action
    return action_cb_task.result()
           ^^^^^^^^^^^^^^^^^^^^^^^
  File "/Users/mariakondakova/Recipe-bot/venv/lib/python3.11/site-packages/telegram/ext/_updater.py", line 367, in polling_action_cb
    updates = await self.bot.get_updates(
              ^^^^^^^^^^^^^^^^^^^^^^^^^^^
  File "/Users/mariakondakova/Recipe-bot/venv/lib/python3.11/site-packages/telegram/ext/_extbot.py", line 647, in get_updates
    updates = await super().get_updates(
              ^^^^^^^^^^^^^^^^^^^^^^^^^^
  File "/Users/mariakondakova/Recipe-bot/venv/lib/python3.11/site-packages/telegram/_bot.py", line 4421, in get_updates
    await self._post(
  File "/Users/mariakondakova/Recipe-bot/venv/lib/python3.11/site-packages/telegram/_bot.py", line 617, in _post
    return await self._do_post(
           ^^^^^^^^^^^^^^^^^^^^
  File "/Users/mariakondakova/Recipe-bot/venv/lib/python3.11/site-packages/telegram/ext/_extbot.py", line 351, in _do_post
    return await super()._do_post(
           ^^^^^^^^^^^^^^^^^^^^^^^
  File "/Users/mariakondakova/Recipe-bot/venv/lib/python3.11/site-packages/telegram/_bot.py", line 646, in _do_post
    result = await request.post(
             ^^^^^^^^^^^^^^^^^^^
  File "/Users/mariakondakova/Recipe-bot/venv/lib/python3.11/site-packages/telegram/request/_baserequest.py", line 202, in post
    result = await self._request_wrapper(
             ^^^^^^^^^^^^^^^^^^^^^^^^^^^^
  File "/Users/mariakondakova/Recipe-bot/venv/lib/python3.11/site-packages/telegram/request/_baserequest.py", line 385, in _request_wrapper
    raise Conflict(message)
telegram.error.Conflict: Conflict: terminated by other getUpdates request; make sure that only one bot instance is running
No error handlers are registered, logging exception.
Traceback (most recent call last):
  File "/Users/mariakondakova/Recipe-bot/venv/lib/python3.11/site-packages/telegram/ext/_updater.py", line 743, in _network_loop_retry
    if not await do_action():
           ^^^^^^^^^^^^^^^^^
  File "/Users/mariakondakova/Recipe-bot/venv/lib/python3.11/site-packages/telegram/ext/_updater.py", line 737, in do_action
    return action_cb_task.result()
           ^^^^^^^^^^^^^^^^^^^^^^^
  File "/Users/mariakondakova/Recipe-bot/venv/lib/python3.11/site-packages/telegram/ext/_updater.py", line 367, in polling_action_cb
    updates = await self.bot.get_updates(
              ^^^^^^^^^^^^^^^^^^^^^^^^^^^
  File "/Users/mariakondakova/Recipe-bot/venv/lib/python3.11/site-packages/telegram/ext/_extbot.py", line 647, in get_updates
    updates = await super().get_updates(
              ^^^^^^^^^^^^^^^^^^^^^^^^^^
  File "/Users/mariakondakova/Recipe-bot/venv/lib/python3.11/site-packages/telegram/_bot.py", line 4421, in get_updates
    await self._post(
  File "/Users/mariakondakova/Recipe-bot/venv/lib/python3.11/site-packages/telegram/_bot.py", line 617, in _post
    return await self._do_post(
           ^^^^^^^^^^^^^^^^^^^^
  File "/Users/mariakondakova/Recipe-bot/venv/lib/python3.11/site-packages/telegram/ext/_extbot.py", line 351, in _do_post
    return await super()._do_post(
           ^^^^^^^^^^^^^^^^^^^^^^^
  File "/Users/mariakondakova/Recipe-bot/venv/lib/python3.11/site-packages/telegram/_bot.py", line 646, in _do_post
    result = await request.post(
             ^^^^^^^^^^^^^^^^^^^
  File "/Users/mariakondakova/Recipe-bot/venv/lib/python3.11/site-packages/telegram/request/_baserequest.py", line 202, in post
    result = await self._request_wrapper(
             ^^^^^^^^^^^^^^^^^^^^^^^^^^^^
  File "/Users/mariakondakova/Recipe-bot/venv/lib/python3.11/site-packages/telegram/request/_baserequest.py", line 385, in _request_wrapper
    raise Conflict(message)
telegram.error.Conflict: Conflict: terminated by other getUpdates request; make sure that only one bot instance is running
No error handlers are registered, logging exception.
Traceback (most recent call last):
  File "/Users/mariakondakova/Recipe-bot/venv/lib/python3.11/site-packages/telegram/ext/_updater.py", line 743, in _network_loop_retry
    if not await do_action():
           ^^^^^^^^^^^^^^^^^
  File "/Users/mariakondakova/Recipe-bot/venv/lib/python3.11/site-packages/telegram/ext/_updater.py", line 737, in do_action
    return action_cb_task.result()
           ^^^^^^^^^^^^^^^^^^^^^^^
  File "/Users/mariakondakova/Recipe-bot/venv/lib/python3.11/site-packages/telegram/ext/_updater.py", line 367, in polling_action_cb
    updates = await self.bot.get_updates(
              ^^^^^^^^^^^^^^^^^^^^^^^^^^^
  File "/Users/mariakondakova/Recipe-bot/venv/lib/python3.11/site-packages/telegram/ext/_extbot.py", line 647, in get_updates
    updates = await super().get_updates(
              ^^^^^^^^^^^^^^^^^^^^^^^^^^
  File "/Users/mariakondakova/Recipe-bot/venv/lib/python3.11/site-packages/telegram/_bot.py", line 4421, in get_updates
    await self._post(
  File "/Users/mariakondakova/Recipe-bot/venv/lib/python3.11/site-packages/telegram/_bot.py", line 617, in _post
    return await self._do_post(
           ^^^^^^^^^^^^^^^^^^^^
  File "/Users/mariakondakova/Recipe-bot/venv/lib/python3.11/site-packages/telegram/ext/_extbot.py", line 351, in _do_post
    return await super()._do_post(
           ^^^^^^^^^^^^^^^^^^^^^^^
  File "/Users/mariakondakova/Recipe-bot/venv/lib/python3.11/site-packages/telegram/_bot.py", line 646, in _do_post
    result = await request.post(
             ^^^^^^^^^^^^^^^^^^^
  File "/Users/mariakondakova/Recipe-bot/venv/lib/python3.11/site-packages/telegram/request/_baserequest.py", line 202, in post
    result = await self._request_wrapper(
             ^^^^^^^^^^^^^^^^^^^^^^^^^^^^
  File "/Users/mariakondakova/Recipe-bot/venv/lib/python3.11/site-packages/telegram/request/_baserequest.py", line 385, in _request_wrapper
    raise Conflict(message)
telegram.error.Conflict: Conflict: terminated by other getUpdates request; make sure that only one bot instance is running
No error handlers are registered, logging exception.
Traceback (most recent call last):
  File "/Users/mariakondakova/Recipe-bot/venv/lib/python3.11/site-packages/telegram/ext/_updater.py", line 743, in _network_loop_retry
    if not await do_action():
           ^^^^^^^^^^^^^^^^^
  File "/Users/mariakondakova/Recipe-bot/venv/lib/python3.11/site-packages/telegram/ext/_updater.py", line 737, in do_action
    return action_cb_task.result()
           ^^^^^^^^^^^^^^^^^^^^^^^
  File "/Users/mariakondakova/Recipe-bot/venv/lib/python3.11/site-packages/telegram/ext/_updater.py", line 367, in polling_action_cb
    updates = await self.bot.get_updates(
              ^^^^^^^^^^^^^^^^^^^^^^^^^^^
  File "/Users/mariakondakova/Recipe-bot/venv/lib/python3.11/site-packages/telegram/ext/_extbot.py", line 647, in get_updates
    updates = await super().get_updates(
              ^^^^^^^^^^^^^^^^^^^^^^^^^^
  File "/Users/mariakondakova/Recipe-bot/venv/lib/python3.11/site-packages/telegram/_bot.py", line 4421, in get_updates
    await self._post(
  File "/Users/mariakondakova/Recipe-bot/venv/lib/python3.11/site-packages/telegram/_bot.py", line 617, in _post
    return await self._do_post(
           ^^^^^^^^^^^^^^^^^^^^
  File "/Users/mariakondakova/Recipe-bot/venv/lib/python3.11/site-packages/telegram/ext/_extbot.py", line 351, in _do_post
    return await super()._do_post(
           ^^^^^^^^^^^^^^^^^^^^^^^
  File "/Users/mariakondakova/Recipe-bot/venv/lib/python3.11/site-packages/telegram/_bot.py", line 646, in _do_post
    result = await request.post(
             ^^^^^^^^^^^^^^^^^^^
  File "/Users/mariakondakova/Recipe-bot/venv/lib/python3.11/site-packages/telegram/request/_baserequest.py", line 202, in post
    result = await self._request_wrapper(
             ^^^^^^^^^^^^^^^^^^^^^^^^^^^^
  File "/Users/mariakondakova/Recipe-bot/venv/lib/python3.11/site-packages/telegram/request/_baserequest.py", line 385, in _request_wrapper
    raise Conflict(message)
telegram.error.Conflict: Conflict: terminated by other getUpdates request; make sure that only one bot instance is running
No error handlers are registered, logging exception.
Traceback (most recent call last):
  File "/Users/mariakondakova/Recipe-bot/venv/lib/python3.11/site-packages/telegram/ext/_updater.py", line 743, in _network_loop_retry
    if not await do_action():
           ^^^^^^^^^^^^^^^^^
  File "/Users/mariakondakova/Recipe-bot/venv/lib/python3.11/site-packages/telegram/ext/_updater.py", line 737, in do_action
    return action_cb_task.result()
           ^^^^^^^^^^^^^^^^^^^^^^^
  File "/Users/mariakondakova/Recipe-bot/venv/lib/python3.11/site-packages/telegram/ext/_updater.py", line 367, in polling_action_cb
    updates = await self.bot.get_updates(
              ^^^^^^^^^^^^^^^^^^^^^^^^^^^
  File "/Users/mariakondakova/Recipe-bot/venv/lib/python3.11/site-packages/telegram/ext/_extbot.py", line 647, in get_updates
    updates = await super().get_updates(
              ^^^^^^^^^^^^^^^^^^^^^^^^^^
  File "/Users/mariakondakova/Recipe-bot/venv/lib/python3.11/site-packages/telegram/_bot.py", line 4421, in get_updates
    await self._post(
  File "/Users/mariakondakova/Recipe-bot/venv/lib/python3.11/site-packages/telegram/_bot.py", line 617, in _post
    return await self._do_post(
           ^^^^^^^^^^^^^^^^^^^^
  File "/Users/mariakondakova/Recipe-bot/venv/lib/python3.11/site-packages/telegram/ext/_extbot.py", line 351, in _do_post
    return await super()._do_post(
           ^^^^^^^^^^^^^^^^^^^^^^^
  File "/Users/mariakondakova/Recipe-bot/venv/lib/python3.11/site-packages/telegram/_bot.py", line 646, in _do_post
    result = await request.post(
             ^^^^^^^^^^^^^^^^^^^
  File "/Users/mariakondakova/Recipe-bot/venv/lib/python3.11/site-packages/telegram/request/_baserequest.py", line 202, in post
    result = await self._request_wrapper(
             ^^^^^^^^^^^^^^^^^^^^^^^^^^^^
  File "/Users/mariakondakova/Recipe-bot/venv/lib/python3.11/site-packages/telegram/request/_baserequest.py", line 385, in _request_wrapper
    raise Conflict(message)
telegram.error.Conflict: Conflict: terminated by other getUpdates request; make sure that only one bot instance is running
No error handlers are registered, logging exception.
Traceback (most recent call last):
  File "/Users/mariakondakova/Recipe-bot/venv/lib/python3.11/site-packages/telegram/ext/_updater.py", line 743, in _network_loop_retry
    if not await do_action():
           ^^^^^^^^^^^^^^^^^
  File "/Users/mariakondakova/Recipe-bot/venv/lib/python3.11/site-packages/telegram/ext/_updater.py", line 737, in do_action
    return action_cb_task.result()
           ^^^^^^^^^^^^^^^^^^^^^^^
  File "/Users/mariakondakova/Recipe-bot/venv/lib/python3.11/site-packages/telegram/ext/_updater.py", line 367, in polling_action_cb
    updates = await self.bot.get_updates(
              ^^^^^^^^^^^^^^^^^^^^^^^^^^^
  File "/Users/mariakondakova/Recipe-bot/venv/lib/python3.11/site-packages/telegram/ext/_extbot.py", line 647, in get_updates
    updates = await super().get_updates(
              ^^^^^^^^^^^^^^^^^^^^^^^^^^
  File "/Users/mariakondakova/Recipe-bot/venv/lib/python3.11/site-packages/telegram/_bot.py", line 4421, in get_updates
    await self._post(
  File "/Users/mariakondakova/Recipe-bot/venv/lib/python3.11/site-packages/telegram/_bot.py", line 617, in _post
    return await self._do_post(
           ^^^^^^^^^^^^^^^^^^^^
  File "/Users/mariakondakova/Recipe-bot/venv/lib/python3.11/site-packages/telegram/ext/_extbot.py", line 351, in _do_post
    return await super()._do_post(
           ^^^^^^^^^^^^^^^^^^^^^^^
  File "/Users/mariakondakova/Recipe-bot/venv/lib/python3.11/site-packages/telegram/_bot.py", line 646, in _do_post
    result = await request.post(
             ^^^^^^^^^^^^^^^^^^^
  File "/Users/mariakondakova/Recipe-bot/venv/lib/python3.11/site-packages/telegram/request/_baserequest.py", line 202, in post
    result = await self._request_wrapper(
             ^^^^^^^^^^^^^^^^^^^^^^^^^^^^
  File "/Users/mariakondakova/Recipe-bot/venv/lib/python3.11/site-packages/telegram/request/_baserequest.py", line 385, in _request_wrapper
    raise Conflict(message)
telegram.error.Conflict: Conflict: terminated by other getUpdates request; make sure that only one bot instance is running
No error handlers are registered, logging exception.
Traceback (most recent call last):
  File "/Users/mariakondakova/Recipe-bot/venv/lib/python3.11/site-packages/telegram/ext/_updater.py", line 743, in _network_loop_retry
    if not await do_action():
           ^^^^^^^^^^^^^^^^^
  File "/Users/mariakondakova/Recipe-bot/venv/lib/python3.11/site-packages/telegram/ext/_updater.py", line 737, in do_action
    return action_cb_task.result()
           ^^^^^^^^^^^^^^^^^^^^^^^
  File "/Users/mariakondakova/Recipe-bot/venv/lib/python3.11/site-packages/telegram/ext/_updater.py", line 367, in polling_action_cb
    updates = await self.bot.get_updates(
              ^^^^^^^^^^^^^^^^^^^^^^^^^^^
  File "/Users/mariakondakova/Recipe-bot/venv/lib/python3.11/site-packages/telegram/ext/_extbot.py", line 647, in get_updates
    updates = await super().get_updates(
              ^^^^^^^^^^^^^^^^^^^^^^^^^^
  File "/Users/mariakondakova/Recipe-bot/venv/lib/python3.11/site-packages/telegram/_bot.py", line 4421, in get_updates
    await self._post(
  File "/Users/mariakondakova/Recipe-bot/venv/lib/python3.11/site-packages/telegram/_bot.py", line 617, in _post
    return await self._do_post(
           ^^^^^^^^^^^^^^^^^^^^
  File "/Users/mariakondakova/Recipe-bot/venv/lib/python3.11/site-packages/telegram/ext/_extbot.py", line 351, in _do_post
    return await super()._do_post(
           ^^^^^^^^^^^^^^^^^^^^^^^
  File "/Users/mariakondakova/Recipe-bot/venv/lib/python3.11/site-packages/telegram/_bot.py", line 646, in _do_post
    result = await request.post(
             ^^^^^^^^^^^^^^^^^^^
  File "/Users/mariakondakova/Recipe-bot/venv/lib/python3.11/site-packages/telegram/request/_baserequest.py", line 202, in post
    result = await self._request_wrapper(
             ^^^^^^^^^^^^^^^^^^^^^^^^^^^^
  File "/Users/mariakondakova/Recipe-bot/venv/lib/python3.11/site-packages/telegram/request/_baserequest.py", line 385, in _request_wrapper
    raise Conflict(message)
telegram.error.Conflict: Conflict: terminated by other getUpdates request; make sure that only one bot instance is running
